Workbook

Sheet Sheet1
A1: instance | B1: k | C1: reps | D1: penalty_mult | E1: optimizer | F1: maxiter | G1: restarts | H1: n_qubits | I1: formulation | J1: final_energy | K1: topk_cost | L1: mp_cost | M1: global_cost | N1: optimal_cost | O1: topk_gap_pct | P1: mp_gap_pct | Q1: global_gap_pct | R1: valid_frac | T1: zero_valid | U1: best_prob_rank | V1: wall_time_s
A2: RioClaroPostToy_5_0 | B2: 1 | C2: 1 | D2: 2 | E2: COBYLA | F2: 50 | G2: 1 | H2: 16 | I2: pos-idx | J2: 133.08199 | K2: inf | L2: inf | M2: inf | N2: 12214.556 | R2: 0 | S2: 0 | T2: TRUE | U2: -1 | V2: 4.82
A3: RioClaroPostToy_5_0 | B3: 1 | C3: 1 | D3: 2 | E3: COBYLA | F3: 50 | G3: 3 | H3: 16 | I3: pos-idx | J3: 125.0288 | K3: 12214.556 | L3: 13028.438 | M3: 12214.556 | N3: 12214.556 | O3: 0 | P3: 6.6632 | Q3: 0 | R3: 0.0013 | S3: 12 | T3: FALSE | U3: 5 | V3: 14.28
A4: RioClaroPostToy_5_0 | B4: 1 | C4: 1 | D4: 2 | E4: COBYLA | F4: 200 | G4: 1 | H4: 16 | I4: pos-idx | J4: 133.08199 | K4: inf | L4: inf | M4: inf | N4: 12214.556 | R4: 0 | S4: 0 | T4: TRUE | U4: -1 | V4: 4.37
A5: RioClaroPostToy_5_0 | B5: 1 | C5: 1 | D5: 2 | E5: COBYLA | F5: 200 | G5: 3 | H5: 16 | I5: pos-idx | J5: 125.0288 | K5: 12214.556 | L5: 13028.438 | M5: 12214.556 | N5: 12214.556 | O5: 0 | P5: 6.6632 | Q5: 0 | R5: 0.0013 | S5: 12 | T5: FALSE | U5: 5 | V5: 14.04
A6: RioClaroPostToy_5_0 | B6: 1 | C6: 1 | D6: 2 | E6: ADAM | F6: 50 | G6: 1 | H6: 16 | I6: pos-idx | J6: 138.21877 | K6: 12214.556 | L6: 14242.717 | M6: 12214.556 | N6: 12214.556 | O6: 0 | P6: 16.6045 | Q6: 0 | R6: 0.0022 | S6: 16 | T6: FALSE | U6: 10 | V6: 0.95
A7: RioClaroPostToy_5_0 | B7: 1 | C7: 1 | D7: 2 | E7: ADAM | F7: 50 | G7: 3 | H7: 16 | I7: pos-idx | J7: 134.33808 | K7: 13576.358 | L7: 13576.358 | M7: 13576.358 | N7: 12214.556 | O7: 11.149 | P7: 11.149 | Q7: 11.149 | R7: 0.0001 | S7: 1 | T7: FALSE | U7: 1 | V7: 2.16
A8: RioClaroPostToy_5_0 | B8: 1 | C8: 1 | D8: 2 | E8: ADAM | F8: 200 | G8: 1 | H8: 16 | I8: pos-idx | J8: 138.21877 | K8: 12214.556 | L8: 14242.717 | M8: 12214.556 | N8: 12214.556 | O8: 0 | P8: 16.6045 | Q8: 0 | R8: 0.0022 | S8: 16 | T8: FALSE | U8: 10 | V8: 1.01
A9: RioClaroPostToy_5_0 | B9: 1 | C9: 1 | D9: 2 | E9: ADAM | F9: 200 | G9: 3 | H9: 16 | I9: pos-idx | J9: 134.33808 | K9: 13576.358 | L9: 13576.358 | M9: 13576.358 | N9: 12214.556 | O9: 11.149 | P9: 11.149 | Q9: 11.149 | R9: 0.0001 | S9: 1 | T9: FALSE | U9: 1 | V9: 2.19
A10: RioClaroPostToy_5_0 | B10: 1 | C10: 1 | D10: 5 | E10: COBYLA | F10: 50 | G10: 1 | H10: 16 | I10: pos-idx | J10: 82.933557 | K10: 12895.062 | L10: 15056.599 | M10: 12214.556 | N10: 12214.556 | O10: 5.5713 | P10: 23.2677 | Q10: 0 | R10: 0.044 | S10: 24 | T10: FALSE | U10: 17 | V10: 5.6
A11: RioClaroPostToy_5_0 | B11: 1 | C11: 1 | D11: 5 | E11: COBYLA | F11: 50 | G11: 3 | H11: 16 | I11: pos-idx | J11: 77.314283 | K11: 13028.438 | L11: 13694.797 | M11: 12214.556 | N11: 12214.556 | O11: 6.6632 | P11: 12.1187 | Q11: 0 | R11: 0.0388 | S11: 24 | T11: FALSE | U11: 12 | V11: 16.53
A12: RioClaroPostToy_5_0 | B12: 1 | C12: 1 | D12: 5 | E12: COBYLA | F12: 200 | G12: 1 | H12: 16 | I12: pos-idx | J12: 82.933557 | K12: 12895.062 | L12: 15056.599 | M12: 12214.556 | N12: 12214.556 | O12: 5.5713 | P12: 23.2677 | Q12: 0 | R12: 0.044 | S12: 24 | T12: FALSE | U12: 17 | V12: 5.71
A13: RioClaroPostToy_5_0 | B13: 1 | C13: 1 | D13: 5 | E13: COBYLA | F13: 200 | G13: 3 | H13: 16 | I13: pos-idx | J13: 77.314283 | K13: 13028.438 | L13: 13694.797 | M13: 12214.556 | N13: 12214.556 | O13: 6.6632 | P13: 12.1187 | Q13: 0 | R13: 0.0388 | S13: 24 | T13: FALSE | U13: 12 | V13: 16.62
A14: RioClaroPostToy_5_0 | B14: 1 | C14: 1 | D14: 5 | E14: ADAM | F14: 50 | G14: 1 | H14: 16 | I14: pos-idx | J14: 365.64322 | K14: 12214.556 | L14: 13860.946 | M14: 12214.556 | N14: 12214.556 | O14: 0 | P14: 13.4789 | Q14: 0 | R14: 0.0015 | S14: 12 | T14: FALSE | U14: 11 | V14: 0.95
A15: RioClaroPostToy_5_0 | B15: 1 | C15: 1 | D15: 5 | E15: ADAM | F15: 50 | G15: 3 | H15: 16 | I15: pos-idx | J15: 323.74447 | K15: inf | L15: inf | M15: inf | N15: 12214.556 | R15: 0 | S15: 0 | T15: TRUE | U15: -1 | V15: 2.19
A16: RioClaroPostToy_5_0 | B16: 1 | C16: 1 | D16: 5 | E16: ADAM | F16: 200 | G16: 1 | H16: 16 | I16: pos-idx | J16: 365.64322 | K16: 12214.556 | L16: 13860.946 | M16: 12214.556 | N16: 12214.556 | O16: 0 | P16: 13.4789 | Q16: 0 | R16: 0.0015 | S16: 12 | T16: FALSE | U16: 11 | V16: 0.94
A17: RioClaroPostToy_5_0 | B17: 1 | C17: 1 | D17: 5 | E17: ADAM | F17: 200 | G17: 3 | H17: 16 | I17: pos-idx | J17: 323.74447 | K17: inf | L17: inf | M17: inf | N17: 12214.556 | R17: 0 | S17: 0 | T17: TRUE | U17: -1 | V17: 2.16
A18: RioClaroPostToy_5_0 | B18: 1 | C18: 1 | D18: 10 | E18: COBYLA | F18: 50 | G18: 1 | H18: 16 | I18: pos-idx | J18: 155.12309 | K18: 12895.062 | L18: 14376.093 | M18: 12214.556 | N18: 12214.556 | O18: 5.5713 | P18: 17.6964 | Q18: 0 | R18: 0.0303 | S18: 24 | T18: FALSE | U18: 17 | V18: 5.04
A19: RioClaroPostToy_5_0 | B19: 1 | C19: 1 | D19: 10 | E19: COBYLA | F19: 50 | G19: 3 | H19: 16 | I19: pos-idx | J19: 155.12309 | K19: 12895.062 | L19: 14376.093 | M19: 12214.556 | N19: 12214.556 | O19: 5.5713 | P19: 17.6964 | Q19: 0 | R19: 0.0303 | S19: 24 | T19: FALSE | U19: 17 | V19: 14.82
A20: RioClaroPostToy_5_0 | B20: 1 | C20: 1 | D20: 10 | E20: COBYLA | F20: 200 | G20: 1 | H20: 16 | I20: pos-idx | J20: 155.12309 | K20: 12895.062 | L20: 14376.093 | M20: 12214.556 | N20: 12214.556 | O20: 5.5713 | P20: 17.6964 | Q20: 0 | R20: 0.0303 | S20: 24 | T20: FALSE | U20: 17 | V20: 5
A21: RioClaroPostToy_5_0 | B21: 1 | C21: 1 | D21: 10 | E21: COBYLA | F21: 200 | G21: 3 | H21: 16 | I21: pos-idx | J21: 155.12309 | K21: 12895.062 | L21: 14376.093 | M21: 12214.556 | N21: 12214.556 | O21: 5.5713 | P21: 17.6964 | Q21: 0 | R21: 0.0303 | S21: 24 | T21: FALSE | U21: 17 | V21: 14.77
A22: RioClaroPostToy_5_0 | B22: 1 | C22: 1 | D22: 10 | E22: ADAM | F22: 50 | G22: 1 | H22: 16 | I22: pos-idx | J22: 751.71396 | K22: 12895.062 | L22: 15056.599 | M22: 12895.062 | N22: 12214.556 | O22: 5.5713 | P22: 23.2677 | Q22: 5.5713 | R22: 0.0018 | S22: 14 | T22: FALSE | U22: 4 | V22: 0.95
A23: RioClaroPostToy_5_0 | B23: 1 | C23: 1 | D23: 10 | E23: ADAM | F23: 50 | G23: 3 | H23: 16 | I23: pos-idx | J23: 636.97144 | K23: 14242.717 | L23: 14242.717 | M23: 14242.717 | N23: 12214.556 | O23: 16.6045 | P23: 16.6045 | Q23: 16.6045 | R23: 0.0001 | S23: 1 | T23: FALSE | U23: 1 | V23: 2.19
A24: RioClaroPostToy_5_0 | B24: 1 | C24: 1 | D24: 10 | E24: ADAM | F24: 200 | G24: 1 | H24: 16 | I24: pos-idx | J24: 751.71396 | K24: 12895.062 | L24: 15056.599 | M24: 12895.062 | N24: 12214.556 | O24: 5.5713 | P24: 23.2677 | Q24: 5.5713 | R24: 0.0018 | S24: 14 | T24: FALSE | U24: 4 | V24: 0.94
A25: RioClaroPostToy_5_0 | B25: 1 | C25: 1 | D25: 10 | E25: ADAM | F25: 200 | G25: 3 | H25: 16 | I25: pos-idx | J25: 636.97144 | K25: 14242.717 | L25: 14242.717 | M25: 14242.717 | N25: 12214.556 | O25: 16.6045 | P25: 16.6045 | Q25: 16.6045 | R25: 0.0001 | S25: 1 | T25: FALSE | U25: 1 | V25: 2.16
A26: RioClaroPostToy_5_0 | B26: 1 | C26: 2 | D26: 2 | E26: COBYLA | F26: 50 | G26: 1 | H26: 16 | I26: pos-idx | J26: 39.219842 | K26: 12214.556 | L26: 14376.093 | M26: 12214.556 | N26: 12214.556 | O26: 0 | P26: 17.6964 | Q26: 0 | R26: 0.0025 | S26: 16 | T26: FALSE | U26: 5 | V26: 6.31
A27: RioClaroPostToy_5_0 | B27: 1 | C27: 2 | D27: 2 | E27: COBYLA | F27: 50 | G27: 3 | H27: 16 | I27: pos-idx | J27: 32.332906 | K27: 12895.062 | L27: 12895.062 | M27: 12214.556 | N27: 12214.556 | O27: 5.5713 | P27: 5.5713 | Q27: 0 | R27: 0.1531 | S27: 24 | T27: FALSE | U27: 20 | V27: 19
A28: RioClaroPostToy_5_0 | B28: 1 | C28: 2 | D28: 2 | E28: COBYLA | F28: 200 | G28: 1 | H28: 16 | I28: pos-idx | J28: 39.219842 | K28: 12214.556 | L28: 14376.093 | M28: 12214.556 | N28: 12214.556 | O28: 0 | P28: 17.6964 | Q28: 0 | R28: 0.0025 | S28: 16 | T28: FALSE | U28: 5 | V28: 6.25
A29: RioClaroPostToy_5_0 | B29: 1 | C29: 2 | D29: 2 | E29: COBYLA | F29: 200 | G29: 3 | H29: 16 | I29: pos-idx | J29: 32.332906 | K29: 12895.062 | L29: 12895.062 | M29: 12214.556 | N29: 12214.556 | O29: 5.5713 | P29: 5.5713 | Q29: 0 | R29: 0.1531 | S29: 24 | T29: FALSE | U29: 20 | V29: 19.19
... A53: RioClaroPostToy_5_0 | B53: 1 | C53: 3 | D53: 2 | E53: COBYLA | F53: 200 | G53: 3 | H53: 16 | I53: pos-idx | J53: 31.635339 | K53: 12214.556 | L53: 12895.062 | M53: 12214.556 | N53: 12214.556 | O53: 0 | P53: 5.5713 | Q53: 0 | R53: 0.0267 | S53: 24 | T53: FALSE | U53: 13 | V53: 33.68
A54: RioClaroPostToy_5_0 | B54: 1 | C54: 3 | D54: 2 | E54: ADAM | F54: 50 | G54: 1 | H54: 16 | I54: pos-idx | J54: 139.09394 | K54: inf | L54: inf | M54: inf | N54: 12214.556 | R54: 0 | S54: 0 | T54: TRUE | U54: -1 | V54: 1.88
A55: RioClaroPostToy_5_0 | B55: 1 | C55: 3 | D55: 2 | E55: ADAM | F55: 50 | G55: 3 | H55: 16 | I55: pos-idx | J55: 128.35093 | K55: 12214.556 | L55: 13576.358 | M55: 12214.556 | N55: 12214.556 | O55: 0 | P55: 11.149 | Q55: 0 | R55: 0.0017 | S55: 10 | T55: FALSE | U55: 10 | V55: 4.81
A56: RioClaroPostToy_5_0 | B56: 1 | C56: 3 | D56: 2 | E56: ADAM | F56: 200 | G56: 1 | H56: 16 | I56: pos-idx | J56: 139.09394 | K56: inf | L56: inf | M56: inf | N56: 12214.556 | R56: 0 | S56: 0 | T56: TRUE | U56: -1 | V56: 1.88
A57: RioClaroPostToy_5_0 | B57: 1 | C57: 3 | D57: 2 | E57: ADAM | F57: 200 | G57: 3 | H57: 16 | I57: pos-idx | J57: 128.35093 | K57: 12214.556 | L57: 13576.358 | M57: 12214.556 | N57: 12214.556 | O57: 0 | P57: 11.149 | Q57: 0 | R57: 0.0017 | S57: 10 | T57: FALSE | U57: 10 | V57: 4.89
A58: RioClaroPostToy_5_0 | B58: 1 | C58: 3 | D58: 5 | E58: COBYLA | F58: 50 | G58: 1 | H58: 16 | I58: pos-idx | J58: 63.92994 | K58: 12214.556 | L58: 13860.946 | M58: 12214.556 | N58: 12214.556 | O58: 0 | P58: 13.4789 | Q58: 0 | R58: 0.181 | S58: 24 | T58: FALSE | U58: 23 | V58: 8.72
A59: RioClaroPostToy_5_0 | B59: 1 | C59: 3 | D59: 5 | E59: COBYLA | F59: 50 | G59: 3 | H59: 16 | I59: pos-idx | J59: 63.92994 | K59: 12214.556 | L59: 13860.946 | M59: 12214.556 | N59: 12214.556 | O59: 0 | P59: 13.4789 | Q59: 0 | R59: 0.181 | S59: 24 | T59: FALSE | U59: 23 | V59: 25.51
A60: RioClaroPostToy_5_0 | B60: 1 | C60: 3 | D60: 5 | E60: COBYLA | F60: 200 | G60: 1 | H60: 16 | I60: pos-idx | J60: 63.09636 | K60: 12214.556 | L60: 13860.946 | M60: 12214.556 | N60: 12214.556 | O60: 0 | P60: 13.4789 | Q60: 0 | R60: 0.181 | S60: 24 | T60: FALSE | U60: 24 | V60: 10.7
A61: RioClaroPostToy_5_0 | B61: 1 | C61: 3 | D61: 5 | E61: COBYLA | F61: 200 | G61: 3 | H61: 16 | I61: pos-idx | J61: 63.09636 | K61: 12214.556 | L61: 13860.946 | M61: 12214.556 | N61: 12214.556 | O61: 0 | P61: 13.4789 | Q61: 0 | R61: 0.181 | S61: 24 | T61: FALSE | U61: 24 | V61: 29.82
A62: RioClaroPostToy_5_0 | B62: 1 | C62: 3 | D62: 5 | E62: ADAM | F62: 50 | G62: 1 | H62: 16 | I62: pos-idx | J62: 342.77668 | K62: inf | L62: inf | M62: inf | N62: 12214.556 | R62: 0 | S62: 0 | T62: TRUE | U62: -1 | V62: 1.99
A63: RioClaroPostToy_5_0 | B63: 1 | C63: 3 | D63: 5 | E63: ADAM | F63: 50 | G63: 3 | H63: 16 | I63: pos-idx | J63: 336.67523 | K63: 12895.062 | L63: 15056.599 | M63: 12895.062 | N63: 12214.556 | O63: 5.5713 | P63: 23.2677 | Q63: 5.5713 | R63: 0.0008 | S63: 7 | T63: FALSE | U63: 3 | V63: 4.83
...

Sheet _ChartData
A1: Config | B1: Restarts = 1 | C1: Restarts = 3 | E1: Fleet Size (k) | F1: Rank = 1 | G1: Rank ≠ 1
A2: maxiter = 50 | B2: 15.2 | C2: 44.7 | E2: k=1 | F2: 24 | G2: 336
A3: maxiter = 200 | B3: 34.8 | C3: 104.4 | E3: k=2 | F3: 106 | G3: 254
E4: k=3 | F4: 90 | G4: 270
E5: k=4 | F5: 221 | G5: 139
A6: Optimizer | B6: maxiter = 50 | C6: maxiter = 200
A7: COBYLA | B7: 23.5 | C7: 31.9
A8: ADAM | B8: 7 | C8: 10.1
A9: SPSA | B9: 88.8 | C9: 264
A12: Optimizer | B12: restarts = 1 | C12: restarts = 3
A13: COBYLA | B13: 13.9 | C13: 41.5
A14: ADAM | B14: 3.9 | C14: 13.2
A15: SPSA | B15: 89.4 | C15: 263.4
A18: Reps (p) | B18: COBYLA | C18: ADAM | D18: SPSA
A19: p = 1 | B19: 11.8 | C19: 2.8
A20: p = 2 | B20: 18.9 | C20: 11.4 | D20: 134.5
A21: p = 3 | B21: 29.5 | C21: 6.6
A22: p = 5 | B22: 50.5 | C22: 13.4 | D22: 218.4

Sheet Time Analysis
A1: QAOA Execution Time vs. Performance Analysis
A3: Optimizer | B3: Reps (p) | C3: MaxIter | D3: Restarts | E3: Total Runs | F3: Avg Time (s) | H3: Optimizer | I3: Avg Time (s) | K3: Reps (p) | L3: Avg Time (s) | N3: Restarts | O3: Avg Time (s) | Q3: MaxIter | R3: Avg Time (s)
A4: ADAM | B4: 1 | C4: 50 | D4: 1 | E4: 36 | F4: 1.9169444 | H4: ADAM | I4: =AVERAGEIF(Sheet1!E:E,H4,Sheet1!V:V) -> 8.5218403 | K4: 1 | L4: =AVERAGEIF(Sheet1!C:C,K4,Sheet1!V:V) -> 41.641319 | N4: 1 | O4: =AVERAGEIF(Sheet1!G:G,N4,Sheet1!V:V) -> 32.28809 | Q4: 50 | R4: =AVERAGEIF(Sheet1!F:F,Q4,Sheet1!V:V) -> 36.427199
A5: ADAM | B5: 1 | C5: 50 | D5: 3 | E5: 36 | F5: 3.3391667 | H5: COBYLA | I5: =AVERAGEIF(Sheet1!E:E,H5,Sheet1!V:V) -> 27.699965 | K5: 2 | L5: =AVERAGEIF(Sheet1!C:C,K5,Sheet1!V:V) -> 54.929907 | N5: 3 | O5: =AVERAGEIF(Sheet1!G:G,N5,Sheet1!V:V) -> 96.066157 | Q5: 200 | R5: =AVERAGEIF(Sheet1!F:F,Q5,Sheet1!V:V) -> 91.927049
A6: ADAM | B6: 1 | C6: 200 | D6: 1 | E6: 36 | F6: 2.1644444 | H6: SPSA | I6: =AVERAGEIF(Sheet1!E:E,H6,Sheet1!V:V) -> 156.30957 | K6: 3 | L6: =AVERAGEIF(Sheet1!C:C,K6,Sheet1!V:V) -> 66.038981
A7: ADAM | B7: 1 | C7: 200 | D7: 3 | E7: 36 | F7: 3.6113889 | K7: 5 | L7: =AVERAGEIF(Sheet1!C:C,K7,Sheet1!V:V) -> 94.098287
A8: ADAM | B8: 2 | C8: 50 | D8: 1 | E8: 36 | F8: 1.8136111
A9: ADAM | B9: 2 | C9: 50 | D9: 3 | E9: 36 | F9: 10.954444
A10: ADAM | B10: 2 | C10: 200 | D10: 1 | E10: 36 | F10: 1.8216667
A11: ADAM | B11: 2 | C11: 200 | D11: 3 | E11: 36 | F11: 30.934722
A12: ADAM | B12: 3 | C12: 50 | D12: 1 | E12: 36 | F12: 2.6658333
A13: ADAM | B13: 3 | C13: 50 | D13: 3 | E13: 36 | F13: 9.8272222
A14: ADAM | B14: 3 | C14: 200 | D14: 1 | E14: 36 | F14: 2.6852778
A15: ADAM | B15: 3 | C15: 200 | D15: 3 | E15: 36 | F15: 11.187222
A16: ADAM | B16: 5 | C16: 50 | D16: 1 | E16: 36 | F16: 8.3430556
A17: ADAM | B17: 5 | C17: 50 | D17: 3 | E17: 36 | F17: 17.001111
A18: ADAM | B18: 5 | C18: 200 | D18: 1 | E18: 36 | F18: 9.7066667
A19: ADAM | B19: 5 | C19: 200 | D19: 3 | E19: 36 | F19: 18.376667
... A51: SPSA | B51: 5 | C51: 200 | D51: 3 | E51: 36 | F51: 490.88889
A52: TOTAL / OVERALL | E52: 1728 | F52: 64.177124

Sheet Validity Analysis
A1: QAOA Complete Failure (zero_valid) Correlation Analysis
A3: 1. Failure Rate by Fleet Size (k)
A4: Fleet Size (k) | B4: Total Runs | C4: Failures | D4: Failure Rate (%)
A5: 1 | B5: 432 | C5: 37 | D5: 8.5648148
A6: 2 | B6: 432 | C6: 118 | D6: 27.314815
A7: 3 | B7: 432 | C7: 111 | D7: 25.694444
A8: 4 | B8: 432 | C8: 171 | D8: 39.583333
A10: 2. Failure Rate by Optimizer
A11: Optimizer | B11: Total Runs | C11: Failures | D11: Failure Rate (%)
A12: ADAM | B12: 576 | C12: 232 | D12: 40.277778 | E12: coblya
A13: COBYLA | B13: 576 | C13: 36 | D13: 6.25
A14: SPSA | B14: 576 | C14: 169 | D14: 29.340278
A16: 3. Failure Rate by Restarts
A17: Restarts | B17: Total Runs | C17: Failures | D17: Failure Rate (%)
A18: 1 | B18: 864 | C18: 284 | D18: 32.87037 | E18: 3
A19: 3 | B19: 864 | C19: 153 | D19: 17.708333
A21: 4. Failure Rate by QAOA Reps (p)
A22: Reps (p) | B22: Total Runs | C22: Failures | D22: Failure Rate (%)
A23: 1 | B23: 432 | C23: 126 | D23: 29.166667
A24: 2 | B24: 432 | C24: 76 | D24: 17.592593 | E24: 2
A25: 3 | B25: 432 | C25: 128 | D25: 29.62963
A26: 5 | B26: 432 | C26: 107 | D26: 24.768519
A28: 5. Failure Rate by MaxIter
A29: MaxIter | B29: Total Runs | C29: Failures | D29: Failure Rate (%)
A30: 50 | B30: 864 | C30: 226 | D30: 26.157407
A31: 200 | B31: 864 | C31: 211 | D31: 24.421296
A32: 6. Failure Rate by Penalty Multiplier
A33: Penalty Mult | B33: Total Runs | C33: Failures | D33: Failure Rate (%)
A34: 2 | B34: =COUNTIF(Sheet1!D:D,A34) -> 576 | C34: =COUNTIFS(Sheet1!D:D,A34,Sheet1!T:T,TRUE) -> 141 | D34: =C34/B34*100 -> 24.479167 | E34: 2
A35: 5 | B35: =COUNTIF(Sheet1!D:D,A35) -> 576 | C35: =COUNTIFS(Sheet1!D:D,A35,Sheet1!T:T,TRUE) -> 149 | D35: =C35/B35*100 -> 25.868056
A36: 10 | B36: =COUNTIF(Sheet1!D:D,A36) -> 576 | C36: =COUNTIFS(Sheet1!D:D,A36,Sheet1!T:T,TRUE) -> 147 | D36: =C36/B36*100 -> 25.520833
A37: 7. Failure Rate by Formulation (pos-idx vs edge)
A38: Formulation | B38: Total Runs | C38: Failures | D38: Failure Rate (%)
A39: pos-idx | B39: =COUNTIF(Sheet1!I:I,A39) -> 432 | C39: =COUNTIFS(Sheet1!I:I,A39,Sheet1!T:T,TRUE) -> 37 | D39: =C39/B39*100 -> 8.5648148
A40: edge | B40: =COUNTIF(Sheet1!I:I,A40) -> 1296 | C40: =COUNTIFS(Sheet1!I:I,A40,Sheet1!T:T,TRUE) -> 400 | D40: =C40/B40*100 -> 30.864198
A44: Key Insights — Validity (Complete Failure Drivers)
A45: # | B45: Driver | C45: Finding
A46: 1 | B46: Optimizer choice dominates | C46: COBYLA fails only 6.3% of the time vs. ADAM 40.3% and SPSA 29.3%. Optimizer selection is the single largest lever on validity — ~6.4x gap between best and worst.
A47: 3 | B47: Restarts materially help | C47: Going from 1 → 3 restarts cuts failure rate nearly in half (32.9% → 17.7%). Multi-start is a cheap and effective reliability booster.
A48: 4 | B48: QAOA depth (p) has weak, non-monotonic effect | C48: Failure rates: p=1: 29.2%, p=2: 17.6%, p=3: 29.6%, p=5: 24.8%. p=2 is the sweet spot; deeper circuits don't reliably improve validity and may add noise.
...

Sheet Ranking Analysis
A1: QAOA Optimal Ranking (best_prob_rank = 1) Correlation Analysis
A3: 1. Rank-1 Distribution by Fleet Size (k)
A4: Fleet Size (k) | B4: Total Runs | C4: Runs with Rank = 1 | D4: Runs with Rank ≠ 1 | E4: Rank-1 Rate (%)
A5: 1 | B5: 432 | C5: 36 | D5: 396 | E5: 8.3333333
A6: 2 | B6: 432 | C6: 126 | D6: 306 | E6: 29.166667
A7: 3 | B7: 432 | C7: 116 | D7: 316 | E7: 26.851852
A8: 4 | B8: 432 | C8: 261 | D8: 171 | E8: 60.416667
A10: Insight: k=4 dominates Rank-1 optimality (60.4%) — the largest search space most cleanly isolates the optimal route when the algorithm converges, contrary to its poor validity score (see Validity Analysis).
A12: 2. Rank-1 Rate by Optimizer
A13: Optimizer | B13: Total Runs | C13: Rank = 1 Count | D13: Rank-1 Rate (%)
A14: ADAM | B14: 576 | C14: 188 | D14: 32.638889
A15: COBYLA | B15: 576 | C15: 177 | D15: 30.729167 | F15: adam
A16: SPSA | B16: 576 | C16: 174 | D16: 30.208333
A18: Insight: ADAM leads Rank-1 rate (32.6%) despite having the highest absolute failure rate (40.3%) — a high-risk/high-reward optimizer: fails often, but when it succeeds it identifies the optimum with highest probability mass.
A20: 3. Rank-1 Rate by QAOA Reps (p)
A21: Reps (p) | B21: Total Runs | C21: Rank = 1 Count | D21: Rank-1 Rate (%)
A22: 1 | B22: 432 | C22: 114 | D22: 26.388889 | F22: 3
A23: 2 | B23: 432 | C23: 129 | D23: 29.861111
A24: 3 | B24: 432 | C24: 150 | D24: 34.722222
A25: 5 | B25: 432 | C25: 146 | D25: 33.796296
A27: 4. Rank-1 Rate by Restarts
A28: Restarts | B28: Total Runs | C28: Rank = 1 Count | D28: Rank-1 Rate (%)
A29: 1 | B29: 864 | C29: 236 | D29: 27.314815 | F29: 3
A30: 3 | B30: 864 | C30: 303 | D30: 35.069444
A32: 5. Rank-1 Rate by MaxIter
A33: MaxIter | B33: Total Runs | C33: Rank = 1 Count | D33: Rank-1 Rate (%)
A34: 50 | B34: =COUNTIF(Sheet1!F:F,A34) -> 864 | C34: =COUNTIFS(Sheet1!F:F,A34,Sheet1!U:U,1) -> 272 | D34: =C34/B34*100 -> 31.481481
A35: 200 | B35: =COUNTIF(Sheet1!F:F,A35) -> 864 | C35: =COUNTIFS(Sheet1!F:F,A35,Sheet1!U:U,1) -> 267 | D35: =C35/B35*100 -> 30.902778
A37: Insight: MaxIter has minimal impact on Rank-1 rate — doubling iterations from 50 to 200 barely shifts optimality concentration. Iteration budget beyond 50 is largely wasted; spend compute on restarts or optimizer choice instead.
A39: 6. Rank-1 Rate by Penalty Multiplier
A40: Penalty Mult | B40: Total Runs | C40: Rank = 1 Count | D40: Rank-1 Rate (%)
A41: 2 | B41: =COUNTIF(Sheet1!D:D,A41) -> 576 | C41: =COUNTIFS(Sheet1!D:D,A41,Sheet1!U:U,1) -> 203 | D41: =C41/B41*100 -> 35.243056 | F41: 2
A42: 5 | B42: =COUNTIF(Sheet1!D:D,A42) -> 576 | C42: =COUNTIFS(Sheet1!D:D,A42,Sheet1!U:U,1) -> 159 | D42: =C42/B42*100 -> 27.604167
A43: 10 | B43: =COUNTIF(Sheet1!D:D,A43) -> 576 | C43: =COUNTIFS(Sheet1!D:D,A43,Sheet1!U:U,1) -> 177 | D43: =C43/B43*100 -> 30.729167
A44: Insight: Penalty=2 delivers the best Rank-1 rate (35.2%); higher penalties (5, 10) degrade optimality by 4.5–7.6pp. Over-penalising constraint violations distorts the cost landscape and pushes QAOA away from the true optimum.
A45: 7. Summary Insights — Validity vs. Optimality Trade-off
A46: • FLEET SIZE PARADOX: k=4 has the HIGHEST failure rate (39.6%) but the HIGHEST Rank-1 rate (60.4%). Larger fleets are harder to solve, but when QAOA converges it produces sharper probability mass on the optimum.
A47: • OPTIMIZER TRADE-OFF: COBYLA is the most RELIABLE (6.3% failure) but offers only middling Rank-1 quality (30.7%). ADAM is the RISKIEST (40.3% failure) yet best Rank-1 (32.6%). SPSA is the worst of both worlds on this dataset.
A48: • DEPTH (reps/p): p=3 delivers the best Rank-1 rate (34.7%); p=2 minimises failures (17.6%). No single depth wins both — tune to priority.
A49: • RESTARTS HELP BOTH: restarts=3 vs restarts=1 cuts failure rate (17.7% vs 32.9%) AND improves Rank-1 rate (35.1% vs 27.3%). Multiple restarts are a strict win.
...

Sheet P_Disaggregated
A1: Table A — Failure Rate (%) by Optimizer × Reps (p) | H1: Table B — Rank-1 Rate (%) by Optimizer × Reps (p)
A2: Optimizer | B2: p=1 | C2: p=2 | D2: p=3 | E2: p=5 | F2: Row Total (%) | H2: Optimizer | I2: p=1 | J2: p=2 | K2: p=3 | L2: p=5 | M2: Row Total (%)
A3: ADAM | B3: =COUNTIFS(Sheet1!$E:$E,$A3,Sheet1!$C:$C,1,Sheet1!$T:$T,TRUE)/COUNTIFS(Sheet1!$E:$E,$A3,Sheet1!$C:$C,1)*100 -> 61.111111 | C3: =COUNTIFS(Sheet1!$E:$E,$A3,Sheet1!$C:$C,2,Sheet1!$T:$T,TRUE)/COUNTIFS(Sheet1!$E:$E,$A3,Sheet1!$C:$C,2)*100 -> 23.611111 | D3: =COUNTIFS(Sheet1!$E:$E,$A3,Sheet1!$C:$C,3,Sheet1!$T:$T,TRUE)/COUNTIFS(Sheet1!$E:$E,$A3,Sheet1!$C:$C,3)*100 -> 43.055556 | E3: =COUNTIFS(Sheet1!$E:$E,$A3,Sheet1!$C:$C,5,Sheet1!$T:$T,TRUE)/COUNTIFS(Sheet1!$E:$E,$A3,Sheet1!$C:$C,5)*100 -> 33.333333 | F3: =COUNTIFS(Sheet1!$E:$E,$A3,Sheet1!$T:$T,TRUE)/COUNTIFS(Sheet1!$E:$E,$A3)*100 -> 40.277778 | H3: ADAM | I3: =COUNTIFS(Sheet1!$E:$E,$H3,Sheet1!$C:$C,1,Sheet1!$U:$U,1)/COUNTIFS(Sheet1!$E:$E,$H3,Sheet1!$C:$C,1)*100 -> 15.277778 | J3: =COUNTIFS(Sheet1!$E:$E,$H3,Sheet1!$C:$C,2,Sheet1!$U:$U,1)/COUNTIFS(Sheet1!$E:$E,$H3,Sheet1!$C:$C,2)*100 -> 37.5 | K3: =COUNTIFS(Sheet1!$E:$E,$H3,Sheet1!$C:$C,3,Sheet1!$U:$U,1)/COUNTIFS(Sheet1!$E:$E,$H3,Sheet1!$C:$C,3)*100 -> 41.666667 | L3: =COUNTIFS(Sheet1!$E:$E,$H3,Sheet1!$C:$C,5,Sheet1!$U:$U,1)/COUNTIFS(Sheet1!$E:$E,$H3,Sheet1!$C:$C,5)*100 -> 36.111111 | M3: =COUNTIFS(Sheet1!$E:$E,$H3,Sheet1!$U:$U,1)/COUNTIFS(Sheet1!$E:$E,$H3)*100 -> 32.638889
A4: COBYLA | B4: =COUNTIFS(Sheet1!$E:$E,$A4,Sheet1!$C:$C,1,Sheet1!$T:$T,TRUE)/COUNTIFS(Sheet1!$E:$E,$A4,Sheet1!$C:$C,1)*100 -> 1.3888889 | C4: =COUNTIFS(Sheet1!$E:$E,$A4,Sheet1!$C:$C,2,Sheet1!$T:$T,TRUE)/COUNTIFS(Sheet1!$E:$E,$A4,Sheet1!$C:$C,2)*100 -> 0 | D4: =COUNTIFS(Sheet1!$E:$E,$A4,Sheet1!$C:$C,3,Sheet1!$T:$T,TRUE)/COUNTIFS(Sheet1!$E:$E,$A4,Sheet1!$C:$C,3)*100 -> 15.277778 | E4: =COUNTIFS(Sheet1!$E:$E,$A4,Sheet1!$C:$C,5,Sheet1!$T:$T,TRUE)/COUNTIFS(Sheet1!$E:$E,$A4,Sheet1!$C:$C,5)*100 -> 8.3333333 | F4: =COUNTIFS(Sheet1!$E:$E,$A4,Sheet1!$T:$T,TRUE)/COUNTIFS(Sheet1!$E:$E,$A4)*100 -> 6.25 | H4: COBYLA | I4: =COUNTIFS(Sheet1!$E:$E,$H4,Sheet1!$C:$C,1,Sheet1!$U:$U,1)/COUNTIFS(Sheet1!$E:$E,$H4,Sheet1!$C:$C,1)*100 -> 27.777778 | J4: =COUNTIFS(Sheet1!$E:$E,$H4,Sheet1!$C:$C,2,Sheet1!$U:$U,1)/COUNTIFS(Sheet1!$E:$E,$H4,Sheet1!$C:$C,2)*100 -> 29.166667 | K4: =COUNTIFS(Sheet1!$E:$E,$H4,Sheet1!$C:$C,3,Sheet1!$U:$U,1)/COUNTIFS(Sheet1!$E:$E,$H4,Sheet1!$C:$C,3)*100 -> 30.555556 | L4: =COUNTIFS(Sheet1!$E:$E,$H4,Sheet1!$C:$C,5,Sheet1!$U:$U,1)/COUNTIFS(Sheet1!$E:$E,$H4,Sheet1!$C:$C,5)*100 -> 35.416667 | M4: =COUNTIFS(Sheet1!$E:$E,$H4,Sheet1!$U:$U,1)/COUNTIFS(Sheet1!$E:$E,$H4)*100 -> 30.729167
A5: SPSA | B5: =COUNTIFS(Sheet1!$E:$E,$A5,Sheet1!$C:$C,1,Sheet1!$T:$T,TRUE)/COUNTIFS(Sheet1!$E:$E,$A5,Sheet1!$C:$C,1)*100 -> 25 | C5: =COUNTIFS(Sheet1!$E:$E,$A5,Sheet1!$C:$C,2,Sheet1!$T:$T,TRUE)/COUNTIFS(Sheet1!$E:$E,$A5,Sheet1!$C:$C,2)*100 -> 29.166667 | D5: =COUNTIFS(Sheet1!$E:$E,$A5,Sheet1!$C:$C,3,Sheet1!$T:$T,TRUE)/COUNTIFS(Sheet1!$E:$E,$A5,Sheet1!$C:$C,3)*100 -> 30.555556 | E5: =COUNTIFS(Sheet1!$E:$E,$A5,Sheet1!$C:$C,5,Sheet1!$T:$T,TRUE)/COUNTIFS(Sheet1!$E:$E,$A5,Sheet1!$C:$C,5)*100 -> 32.638889 | F5: =COUNTIFS(Sheet1!$E:$E,$A5,Sheet1!$T:$T,TRUE)/COUNTIFS(Sheet1!$E:$E,$A5)*100 -> 29.340278 | H5: SPSA | I5: =COUNTIFS(Sheet1!$E:$E,$H5,Sheet1!$C:$C,1,Sheet1!$U:$U,1)/COUNTIFS(Sheet1!$E:$E,$H5,Sheet1!$C:$C,1)*100 -> 36.111111 | J5: =COUNTIFS(Sheet1!$E:$E,$H5,Sheet1!$C:$C,2,Sheet1!$U:$U,1)/COUNTIFS(Sheet1!$E:$E,$H5,Sheet1!$C:$C,2)*100 -> 22.916667 | K5: =COUNTIFS(Sheet1!$E:$E,$H5,Sheet1!$C:$C,3,Sheet1!$U:$U,1)/COUNTIFS(Sheet1!$E:$E,$H5,Sheet1!$C:$C,3)*100 -> 31.944444 | L5: =COUNTIFS(Sheet1!$E:$E,$H5,Sheet1!$C:$C,5,Sheet1!$U:$U,1)/COUNTIFS(Sheet1!$E:$E,$H5,Sheet1!$C:$C,5)*100 -> 29.861111 | M5: =COUNTIFS(Sheet1!$E:$E,$H5,Sheet1!$U:$U,1)/COUNTIFS(Sheet1!$E:$E,$H5)*100 -> 30.208333
A6: Col Total (%) | B6: =COUNTIFS(Sheet1!$C:$C,1,Sheet1!$T:$T,TRUE)/COUNTIF(Sheet1!$C:$C,1)*100 -> 29.166667 | C6: =COUNTIFS(Sheet1!$C:$C,2,Sheet1!$T:$T,TRUE)/COUNTIF(Sheet1!$C:$C,2)*100 -> 17.592593 | D6: =COUNTIFS(Sheet1!$C:$C,3,Sheet1!$T:$T,TRUE)/COUNTIF(Sheet1!$C:$C,3)*100 -> 29.62963 | E6: =COUNTIFS(Sheet1!$C:$C,5,Sheet1!$T:$T,TRUE)/COUNTIF(Sheet1!$C:$C,5)*100 -> 24.768519 | F6: =COUNTIF(Sheet1!$T:$T,TRUE)/(COUNTIF(Sheet1!$T:$T,TRUE)+COUNTIF(Sheet1!$T:$T,FALSE))*100 -> 25.289352 | H6: Col Total (%) | I6: =COUNTIFS(Sheet1!$C:$C,1,Sheet1!$U:$U,1)/COUNTIF(Sheet1!$C:$C,1)*100 -> 26.388889 | J6: =COUNTIFS(Sheet1!$C:$C,2,Sheet1!$U:$U,1)/COUNTIF(Sheet1!$C:$C,2)*100 -> 29.861111 | K6: =COUNTIFS(Sheet1!$C:$C,3,Sheet1!$U:$U,1)/COUNTIF(Sheet1!$C:$C,3)*100 -> 34.722222 | L6: =COUNTIFS(Sheet1!$C:$C,5,Sheet1!$U:$U,1)/COUNTIF(Sheet1!$C:$C,5)*100 -> 33.796296 | M6: =COUNTIF(Sheet1!$U:$U,1)/(COUNTIF(Sheet1!$T:$T,TRUE)+COUNTIF(Sheet1!$T:$T,FALSE))*100 -> 31.19213
A8: Note: COBYLA row is highlighted green — clean signal for thesis reporting. Table C shows the monotonic depth-scaling effect most cleanly (COBYLA row: valid_frac grows ~8× from p=1 to p=5 on non-failed runs).

Sheet MaxIter_Disaggregated
A1: Table A — Failure Rate (%) by Optimizer × MaxIter | F1: Table B — Rank-1 Rate (%) by Optimizer × MaxIter
A2: Optimizer | B2: maxiter=50 | C2: maxiter=200 | D2: Δ (200 − 50) | F2: Optimizer | G2: maxiter=50 | H2: maxiter=200 | I2: Δ (200 − 50)
A3: ADAM | B3: =COUNTIFS(Sheet1!$E:$E,$A3,Sheet1!$F:$F,50,Sheet1!$T:$T,TRUE)/COUNTIFS(Sheet1!$E:$E,$A3,Sheet1!$F:$F,50)*100 -> 40.277778 | C3: =COUNTIFS(Sheet1!$E:$E,$A3,Sheet1!$F:$F,200,Sheet1!$T:$T,TRUE)/COUNTIFS(Sheet1!$E:$E,$A3,Sheet1!$F:$F,200)*100 -> 40.277778 | D3: =C3-B3 -> 0 | F3: ADAM | G3: =COUNTIFS(Sheet1!$E:$E,$F3,Sheet1!$F:$F,50,Sheet1!$U:$U,1)/COUNTIFS(Sheet1!$E:$E,$F3,Sheet1!$F:$F,50)*100 -> 32.638889 | H3: =COUNTIFS(Sheet1!$E:$E,$F3,Sheet1!$F:$F,200,Sheet1!$U:$U,1)/COUNTIFS(Sheet1!$E:$E,$F3,Sheet1!$F:$F,200)*100 -> 32.638889 | I3: =H3-G3 -> 0
A4: COBYLA | B4: =COUNTIFS(Sheet1!$E:$E,$A4,Sheet1!$F:$F,50,Sheet1!$T:$T,TRUE)/COUNTIFS(Sheet1!$E:$E,$A4,Sheet1!$F:$F,50)*100 -> 6.25 | C4: =COUNTIFS(Sheet1!$E:$E,$A4,Sheet1!$F:$F,200,Sheet1!$T:$T,TRUE)/COUNTIFS(Sheet1!$E:$E,$A4,Sheet1!$F:$F,200)*100 -> 6.25 | D4: =C4-B4 -> 0 | F4: COBYLA | G4: =COUNTIFS(Sheet1!$E:$E,$F4,Sheet1!$F:$F,50,Sheet1!$U:$U,1)/COUNTIFS(Sheet1!$E:$E,$F4,Sheet1!$F:$F,50)*100 -> 31.25 | H4: =COUNTIFS(Sheet1!$E:$E,$F4,Sheet1!$F:$F,200,Sheet1!$U:$U,1)/COUNTIFS(Sheet1!$E:$E,$F4,Sheet1!$F:$F,200)*100 -> 30.208333 | I4: =H4-G4 -> -1.0416667
A5: SPSA | B5: =COUNTIFS(Sheet1!$E:$E,$A5,Sheet1!$F:$F,50,Sheet1!$T:$T,TRUE)/COUNTIFS(Sheet1!$E:$E,$A5,Sheet1!$F:$F,50)*100 -> 31.944444 | C5: =COUNTIFS(Sheet1!$E:$E,$A5,Sheet1!$F:$F,200,Sheet1!$T:$T,TRUE)/COUNTIFS(Sheet1!$E:$E,$A5,Sheet1!$F:$F,200)*100 -> 26.736111 | D5: =C5-B5 -> -5.2083333 | F5: SPSA | G5: =COUNTIFS(Sheet1!$E:$E,$F5,Sheet1!$F:$F,50,Sheet1!$U:$U,1)/COUNTIFS(Sheet1!$E:$E,$F5,Sheet1!$F:$F,50)*100 -> 30.555556 | H5: =COUNTIFS(Sheet1!$E:$E,$F5,Sheet1!$F:$F,200,Sheet1!$U:$U,1)/COUNTIFS(Sheet1!$E:$E,$F5,Sheet1!$F:$F,200)*100 -> 29.861111 | I5: =H5-G5 -> -0.69444444
A7: Note: SPSA highlighted pink — the ONLY optimizer where MaxIter materially affects performance. ADAM and COBYLA deltas are exactly 0 to 4 decimals, indicating convergence saturation well below maxiter=50.
